Workbook

Sheet ORCAMENTOS
A1: RELATÓRIO ORCAMENTOS
A10: DATA | B10: Nº DE ORÇA | C10: REV. | D10: INSTALADOR | E10: NOME DA OBRA | F10: TIPO DE OBRA | G10: VENDEDOR | H10: CONTATO | I10: VALOR BRUTO | J10: COMISSÃO | K10: M2 | L10: PRIORIDADE | M10: STATUS | N10: CONCORRENTE | O10: MOTIVO | P10: VALOR CONCORRENTE | Q10: PROJETISTA | R10: ESPECIFICAÇÕES | U10: COMISSÃO 10mm | W10: VALOR
A11: 45660 | B11: 1 | D11: KEEVA TEIC | E11: - | G11: Michel | H11: Rachel | I11: 3411.11 | K11: 24 | L11: FECHADO | N11: - | P11: - | Q11: - | R11: - | U11: 0.07 | V11: - | W11: 148.05 | X11: a | Y11: 164.5
A12: 45663 | B12: 2 | D12: SOLAR AR | E12: HOSPITAL DE REGISTRO - SIRIO LIBANES - DUTOS CENTRO CIRURGICO | G12: Michel | H12: Claudenir | I12: 8092.7 | K12: 96 | L12: FECHADO | N12: - | P12: - | Q12: - | R12: - | U12: 0.06 | V12: - | W12: 144.82 | X12: a | Y12: 148.04
A13: 45663 | B13: 3 | D13: INOVECTOR | E13: HOSP. MORUMBI_SADT | G13: Fernando | H13: Eliete | I13: 14294.94 | K13: 192 | L13: FECHADO | N13: - | P13: - | Q13: - | R13: - | U13: 0.05 | V13: - | W13: 134.64 | X13: a | Y13: 144.81
A14: 45663 | B14: 4 | D14: REWELL OTAVIO | E14: ENG BRUNO NY TOWER | G14: Gabriel | H14: Rewell | I14: 2259.26 | K14: 24 | L14: CANCELADO | N14: - | P14: - | Q14: - | R14: - | U14: 0.04 | V14: - | W14: 125.83 | X14: a | Y14: 134.63
A15: 45663 | B15: 5 | D15: INOVECTOR | E15: VILLA LOBOS - REQ 2.04 | G15: Fernando | H15: Cristina | I15: 6933.2 | K15: 96 | L15: FECHADO | N15: - | P15: - | Q15: - | R15: - | U15: 0.03 | V15: - | W15: 118.08 | X15: a | Y15: 125.82
A16: 45663 | B16: 6 | D16: REWELL OTAVIO | E16: RESIDENCIA UNIFAMILIAR - FERNANDO PORTOLANI DE ANDRADE | G16: Gabriel | H16: Rewell | I16: 9106.66 | K16: 72 | L16: CANCELADO | N16: - | P16: - | Q16: COLD SPACE | R16: CHAPA DE ACO GALVANIZADO | U16: 0.02 | V16: - | W16: 111.24 | X16: a | Y16: 118.07
A17: 45663 | B17: 7 | D17: REWELL OTAVIO | E17: SALA 104 - NY TOWER - ARACATUBA - SP | G17: Gabriel | H17: Rewell | I17: 26029.3 | K17: 240 | L17: CANCELADO | N17: - | P17: - | Q17: COLD SPACE | R17: CHAPA DE ACO GALVANIZADO
A18: 45663 | B18: 8 | D18: GRUPO R1 | E18: - | G18: Gabriel | H18: Janaina | I18: 3232.69 | K18: - | L18: CANCELADO | M18: Negociando | N18: - | P18: - | Q18: - | R18: -
A19: 45663 | B19: 9 | D19: AWA AR CONDICIONADO | E19: ATACADAO - LAURO DE FREITAS CAJI - BA | G19: Guilherme | H19: Maria Julia | I19: 175342.6 | K19: 1752 | L19: CANCELADO | N19: - | P19: - | Q19: ARCO + | R19: N/E | U19: COMISSÃO 20mm | W19: VALOR
A20: 45663 | B20: 10 | D20: CONSTARCO | E20: - | G20: Fernando | H20: Fabricio | I20: 297411.92 | K20: 3408 | L20: CANCELADO | M20: PERDERAM A OBRA | N20: - | P20: - | Q20: - | R20: - | U20: 0.07 | V20: - | W20: 181.58 | X20: a | Y20: 201.76
A21: 45663 | B21: 11 | D21: INOVECTOR | E21: ANALIA FRANCO - REQ 2.03 | G21: Fernando | H21: Eliete | I21: 9352.59 | K21: 144 | L21: FECHADO | N21: - | P21: - | Q21: - | R21: - | U21: 0.06 | V21: - | W21: 177.86 | X21: a | Y21: 181.57
A22: 45663 | B22: 12 | D22: INOVECTOR | E22: HOSP.OSASCO - REQ 2.04 | G22: Fernando | H22: Cristina | I22: 169.83 | K22: - | L22: CANCELADO | N22: - | P22: - | Q22: - | R22: - | U22: 0.05 | V22: - | W22: 165.39 | X22: a | Y22: 177.85
A23: 45663 | B23: 13 | D23: AIR SUPPLY | E23: ASSAI ATACADISTA - SJRP PALESTRA - RENOVACAO | G23: Gabriel | H23: Pedro | I23: 51413.93 | K23: 624 | L23: CANCELADO | N23: - | P23: - | Q23: PLANENRAC | R23: N/E | U23: 0.04 | V23: - | W23: 154.54 | X23: a | Y23: 165.38
A24: 45664 | B24: 14 | D24: GSA DUTOS | E24: - | G24: Gabriel | H24: Geraldo | I24: 835.52 | K24: 4.8 | L24: CANCELADO | N24: - | P24: - | Q24: - | R24: - | U24: 0.03 | V24: - | W24: 145.03 | X24: a | Y24: 154.53
A25: 45664 | B25: 15 | D25: CATELAN | E25: - | G25: Gabriel | H25: Priscila | I25: 2024.86 | K25: 26.4 | L25: CANCELADO | M25: Apenas consulta | N25: - | P25: - | Q25: - | R25: - | U25: 0.02 | V25: - | W25: 136.61 | X25: a | Y25: 145.02
A26: 45664 | B26: 16 | D26: DUCTBUSTERS | E26: - | G26: Michel | H26: Camila | I26: 947.84 | K26: - | L26: FECHADO | N26: - | P26: - | Q26: - | R26: -
A27: 45664 | B27: 17 | D27: AIRPLAN | E27: SHOPPING CENTER - MISTRAL - JK IGUATEMI | G27: Gabriel | H27: Laercio | I27: 8557.66 | K27: 96 | L27: CANCELADO | N27: - | P27: - | Q27: FORTIORE SP | R27: MPU
A28: 45664 | B28: 18 | D28: CIVIL AR | E28: THYSSENKRUPP - POÇOS DE CALDAS - MG | G28: Fernando | H28: Atila | I28: 12090.52 | K28: 912 | L28: FECHADO | M28: Aguardando aprovação | N28: - | P28: - | Q28: CIVIL AR | R28: MPU | U28: COMISSÃO 30mm | W28: VALOR
A29: 45664 | B29: 19 | D29: EKO CLIMAX | E29: - | G29: Michel | H29: Rogerio | I29: 8569.14 | K29: 72 | L29: FECHADO | N29: - | P29: - | Q29: - | R29: - | U29: 0.07 | V29: - | W29: 337.68 | X29: a | Y29: 375.2
A30: 45664 | B30: 20 | D30: FAZENG | E30: CLÍNICA PAULISTA - 13º ANDAR - BELA VISTA - SP | G30: Gabriel | H30: Andrey | I30: 15600.04 | K30: 144 | L30: CANCELADO | M30: Aguardando aprovação | N30: - | P30: - | Q30: FEZENG | R30: N/E | U30: 0.06 | V30: - | W30: 328.72 | X30: a | Y30: 337.67
A31: 45664 | B31: 21 | D31: HELP AIR | E31: - | G31: Gabriel | H31: Joyce | I31: 2288.37 | K31: 24 | L31: CANCELADO | N31: - | P31: - | Q31: - | R31: - | U31: 0.05 | V31: - | W31: 305.64 | X31: a | Y31: 328.71
A32: 45664 | B32: 22 | D32: DUTOLEVE | E32: GESTAMP - TATUAPE - SP | G32: Gabriel | H32: Newton | I32: 4668.85 | K32: 48 | L32: CANCELADO | N32: - | P32: - | Q32: MLF ENGENHARIA | R32: N/E | U32: 0.04 | V32: - | W32: 285.59 | X32: a | Y32: 305.63
A33: 45664 | B33: 23 | D33: AMS INSTALACOES | E33: COMPER - BELVEDERE | G33: Gabriel | H33: Almir | I33: 86323.42 | K33: 1200 | L33: FECHADO | M33: - | N33: - | O33: - | P33: - | Q33: - | R33: - | U33: 0.03 | V33: - | W33: 268.02 | X33: a | Y33: 285.58
A34: 45665 | B34: 24 | D34: INTEG ENGENHARIA | E34: - | G34: Fernando | H34: Angela | I34: 16406.46 | K34: - | L34: PERDIDO | M34: MULTIVAC - COND PGTO | N34: MULTIVAC | O34: COND. PGTO | P34: - | Q34: - | R34: - | U34: 0.02 | V34: - | W34: 252.57 | X34: a | Y34: 268.01
A35: 45665 | B35: 25 | D35: ENEBRAS | E35: 3671_GRAAC - 3671-24 - GRAAC - 1° E 7° ANDAR | G35: Michel | H35: Bruna | I35: 17023.2 | K35: 264 | L35: FECHADO | M35: Aguardando aprovação | N35: - | O35: - | P35: - | Q35: - | R35: -
A36: 45664 | B36: 26 | D36: UNION RHAC | E36: NISSIN CHOCOLATE | G36: Emanuel | H36: Vinicius | I36: 76571.13 | K36: 888 | L36: FECHADO | M36: - | N36: - | O36: - | P36: - | Q36: - | R36: -
A37: 45665 | B37: 27 | D37: ADALTA ENGENHARIA | E37: COPERMED - POUSO ALGRE - MG | G37: Fernando | H37: Joao | I37: 70206.27 | K37: 840 | L37: FECHADO | M37: - | N37: - | O37: - | P37: - | Q37: - | R37: -
A38: 45665 | B38: 28 | D38: K SET | E38: - | G38: Gabriel | H38: Bruna | I38: 1595.63 | K38: 24 | L38: FECHADO | M38: - | N38: - | O38: - | P38: - | Q38: - | R38: -
A39: 45665 | B39: 29 | D39: COLDTERMICA | E39: RNR - FLAMBOYANT - GO | G39: Gabriel | H39: Gabriella | I39: 6177.05 | K39: 48 | L39: CANCELADO | M39: - | N39: - | O39: - | P39: - | Q39: - | R39: -
A40: 45665 | B40: 30 | D40: R1 SOLUCOES | E40: - | G40: Gabriel | H40: Janaina | I40: 3975.32 | K40: 48 | L40: CANCELADO | M40: Negociando | N40: - | O40: - | P40: - | Q40: - | R40: -
A41: 45665 | B41: 31 | D41: GF ENGENHARIA | E41: - | G41: Gabriel | H41: Ricardo | I41: 728.5 | K41: - | L41: CANCELADO | M41: - | N41: - | O41: - | P41: - | Q41: - | R41: -
A42: 45665 | B42: 32 | D42: NEWSET | E42: HOSPITAL SABARA | G42: Aldavir | H42: Rodrigo | I42: 1207781.3 | K42: 15144 | L42: CANCELADO | M42: FECHADO PELA ARPOL | N42: - | O42: - | P42: - | Q42: - | R42: -
A43: 45665 | B43: 33 | D43: NEWSET | E43: HOSPITAL SÃO LUIZ - OSASCO | G43: Aldavir | H43: Felipe | I43: 48379.54 | K43: 528 | L43: CANCELADO | M43: - | N43: - | O43: - | P43: - | Q43: - | R43: -
A44: 45665 | B44: 34 | D44: AIR GREEN | E44: - | G44: Fernando | H44: Renata | I44: 3110.21 | K44: 48 | L44: FECHADO | M44: - | N44: - | O44: - | P44: - | Q44: - | R44: -
A45: 45665 | B45: 35 | D45: CARLOS ANTONIO | E45: LABORATÓRIO QUÍMICO FARMACÊUTICO DA AERONÁUTICA - LAQFA | G45: Emanuel | H45: Carlos | I45: 61538.58 | K45: 672 | L45: CANCELADO | M45: Em vias de fechar, mas cliente final está tentando compraar pelo Rio | N45: - | O45: - | P45: - | Q45: CAMALEAO ENGENHARIA | R45: N/E
A46: 45665 | B46: 36 | D46: ECOLOGIC AIR | E46: ATACADAO - PALMAS III - TO | G46: Michel | H46: Genilson | I46: 257079.26 | K46: 2592 | L46: CANCELADO | M46: - | N46: - | O46: - | P46: - | Q46: PLANENRAC | R46: N/E
A47: 45665 | B47: 37 | D47: ECOLOGIC AIR | E47: ATACADAO - LOJA OSASCO PANORAMICA II - SP | G47: Michel | H47: Genilson | I47: 238482.66 | K47: 2402.4 | L47: CANCELADO | M47: - | N47: - | O47: - | P47: - | Q47: PLANENRAC | R47: N/E
A48: 45665 | B48: 38 | D48: ECOLOGIC AIR | E48: ATACADAO - REDENCAO - PA | G48: Michel | H48: Genilson | I48: 170730.37 | K48: 1729.2 | L48: CANCELADO | M48: - | N48: - | O48: - | P48: - | Q48: PLANENRAC | R48: N/E
...

Sheet FOLLOW-UP
A1: =TODAY() -> 46176 | B1: RESUMO DOS ORÇAMENTOS - ALU-PIR
A2: Data | B2: Número | C2: Revisão | D2: Cliente | E2: Obra | F2: Vendedor | G2: Contato | H2: Valor | I2: Comissão | J2: STATUS | K2: ATUALIZAÇÃO | L2: ESPECIFICAÇÃO
A3: =IF(ORCAMENTOS!A11="","",ORCAMENTOS!A11) -> 45660 | B3: =IF(ORCAMENTOS!B11="","",ORCAMENTOS!B11) -> 1 | C3: =IF(ORCAMENTOS!C11="","",ORCAMENTOS!C11) | D3: =IF(ORCAMENTOS!D11="","",ORCAMENTOS!D11) -> KEEVA TEIC | E3: =IF(ORCAMENTOS!E11="","",ORCAMENTOS!E11) -> - | F3: =IF(ORCAMENTOS!G11="","",ORCAMENTOS!G11) -> Michel | G3: =IF(ORCAMENTOS!H11="","",ORCAMENTOS!H11) -> Rachel | H3: =IF(ORCAMENTOS!I11="","",ORCAMENTOS!I11) -> 3411.11 | I3: =IF(ORCAMENTOS!J11="","",ORCAMENTOS!J11) | J3: =IF(ORCAMENTOS!L11="","",ORCAMENTOS!L11) -> FECHADO | K3: =IF(ORCAMENTOS!M11="","",ORCAMENTOS!M11) | L3: =IF(ORCAMENTOS!R11="","",ORCAMENTOS!R11) -> -
A4: =IF(ORCAMENTOS!A12="","",ORCAMENTOS!A12) -> 45663 | B4: =IF(ORCAMENTOS!B12="","",ORCAMENTOS!B12) -> 2 | C4: =IF(ORCAMENTOS!C12="","",ORCAMENTOS!C12) | D4: =IF(ORCAMENTOS!D12="","",ORCAMENTOS!D12) -> SOLAR AR | E4: =IF(ORCAMENTOS!E12="","",ORCAMENTOS!E12) -> HOSPITAL DE REGISTRO - SIRIO LIBANES - DUTOS CENTRO CIRURGICO | F4: =IF(ORCAMENTOS!G12="","",ORCAMENTOS!G12) -> Michel | G4: =IF(ORCAMENTOS!H12="","",ORCAMENTOS!H12) -> Claudenir | H4: =IF(ORCAMENTOS!I12="","",ORCAMENTOS!I12) -> 8092.7 | I4: =IF(ORCAMENTOS!J12="","",ORCAMENTOS!J12) | J4: =IF(ORCAMENTOS!L12="","",ORCAMENTOS!L12) -> FECHADO | K4: =IF(ORCAMENTOS!M12="","",ORCAMENTOS!M12) | L4: =IF(ORCAMENTOS!R12="","",ORCAMENTOS!R12) -> -
A5: =IF(ORCAMENTOS!A13="","",ORCAMENTOS!A13) -> 45663 | B5: =IF(ORCAMENTOS!B13="","",ORCAMENTOS!B13) -> 3 | C5: =IF(ORCAMENTOS!C13="","",ORCAMENTOS!C13) | D5: =IF(ORCAMENTOS!D13="","",ORCAMENTOS!D13) -> INOVECTOR | E5: =IF(ORCAMENTOS!E13="","",ORCAMENTOS!E13) -> HOSP. MORUMBI_SADT | F5: =IF(ORCAMENTOS!G13="","",ORCAMENTOS!G13) -> Fernando | G5: =IF(ORCAMENTOS!H13="","",ORCAMENTOS!H13) -> Eliete | H5: =IF(ORCAMENTOS!I13="","",ORCAMENTOS!I13) -> 14294.94 | I5: =IF(ORCAMENTOS!J13="","",ORCAMENTOS!J13) | J5: =IF(ORCAMENTOS!L13="","",ORCAMENTOS!L13) -> FECHADO | K5: =IF(ORCAMENTOS!M13="","",ORCAMENTOS!M13) | L5: =IF(ORCAMENTOS!R13="","",ORCAMENTOS!R13) -> -
A6: =IF(ORCAMENTOS!A14="","",ORCAMENTOS!A14) -> 45663 | B6: =IF(ORCAMENTOS!B14="","",ORCAMENTOS!B14) -> 4 | C6: =IF(ORCAMENTOS!C14="","",ORCAMENTOS!C14) | D6: =IF(ORCAMENTOS!D14="","",ORCAMENTOS!D14) -> REWELL OTAVIO | E6: =IF(ORCAMENTOS!E14="","",ORCAMENTOS!E14) -> ENG BRUNO NY TOWER | F6: =IF(ORCAMENTOS!G14="","",ORCAMENTOS!G14) -> Gabriel | G6: =IF(ORCAMENTOS!H14="","",ORCAMENTOS!H14) -> Rewell | H6: =IF(ORCAMENTOS!I14="","",ORCAMENTOS!I14) -> 2259.26 | I6: =IF(ORCAMENTOS!J14="","",ORCAMENTOS!J14) | J6: =IF(ORCAMENTOS!L14="","",ORCAMENTOS!L14) -> CANCELADO | K6: =IF(ORCAMENTOS!M14="","",ORCAMENTOS!M14) | L6: =IF(ORCAMENTOS!R14="","",ORCAMENTOS!R14) -> -
A7: =IF(ORCAMENTOS!A15="","",ORCAMENTOS!A15) -> 45663 | B7: =IF(ORCAMENTOS!B15="","",ORCAMENTOS!B15) -> 5 | C7: =IF(ORCAMENTOS!C15="","",ORCAMENTOS!C15) | D7: =IF(ORCAMENTOS!D15="","",ORCAMENTOS!D15) -> INOVECTOR | E7: =IF(ORCAMENTOS!E15="","",ORCAMENTOS!E15) -> VILLA LOBOS - REQ 2.04 | F7: =IF(ORCAMENTOS!G15="","",ORCAMENTOS!G15) -> Fernando | G7: =IF(ORCAMENTOS!H15="","",ORCAMENTOS!H15) -> Cristina | H7: =IF(ORCAMENTOS!I15="","",ORCAMENTOS!I15) -> 6933.2 | I7: =IF(ORCAMENTOS!J15="","",ORCAMENTOS!J15) | J7: =IF(ORCAMENTOS!L15="","",ORCAMENTOS!L15) -> FECHADO | K7: =IF(ORCAMENTOS!M15="","",ORCAMENTOS!M15) | L7: =IF(ORCAMENTOS!R15="","",ORCAMENTOS!R15) -> -
A8: =IF(ORCAMENTOS!A16="","",ORCAMENTOS!A16) -> 45663 | B8: =IF(ORCAMENTOS!B16="","",ORCAMENTOS!B16) -> 6 | C8: =IF(ORCAMENTOS!C16="","",ORCAMENTOS!C16) | D8: =IF(ORCAMENTOS!D16="","",ORCAMENTOS!D16) -> REWELL OTAVIO | E8: =IF(ORCAMENTOS!E16="","",ORCAMENTOS!E16) -> RESIDENCIA UNIFAMILIAR - FERNANDO PORTOLANI DE ANDRADE | F8: =IF(ORCAMENTOS!G16="","",ORCAMENTOS!G16) -> Gabriel | G8: =IF(ORCAMENTOS!H16="","",ORCAMENTOS!H16) -> Rewell | H8: =IF(ORCAMENTOS!I16="","",ORCAMENTOS!I16) -> 9106.66 | I8: =IF(ORCAMENTOS!J16="","",ORCAMENTOS!J16) | J8: =IF(ORCAMENTOS!L16="","",ORCAMENTOS!L16) -> CANCELADO | K8: =IF(ORCAMENTOS!M16="","",ORCAMENTOS!M16) | L8: =IF(ORCAMENTOS!R16="","",ORCAMENTOS!R16) -> CHAPA DE ACO GALVANIZADO
A9: =IF(ORCAMENTOS!A17="","",ORCAMENTOS!A17) -> 45663 | B9: =IF(ORCAMENTOS!B17="","",ORCAMENTOS!B17) -> 7 | C9: =IF(ORCAMENTOS!C17="","",ORCAMENTOS!C17) | D9: =IF(ORCAMENTOS!D17="","",ORCAMENTOS!D17) -> REWELL OTAVIO | E9: =IF(ORCAMENTOS!E17="","",ORCAMENTOS!E17) -> SALA 104 - NY TOWER - ARACATUBA - SP | F9: =IF(ORCAMENTOS!G17="","",ORCAMENTOS!G17) -> Gabriel | G9: =IF(ORCAMENTOS!H17="","",ORCAMENTOS!H17) -> Rewell | H9: =IF(ORCAMENTOS!I17="","",ORCAMENTOS!I17) -> 26029.3 | I9: =IF(ORCAMENTOS!J17="","",ORCAMENTOS!J17) | J9: =IF(ORCAMENTOS!L17="","",ORCAMENTOS!L17) -> CANCELADO | K9: =IF(ORCAMENTOS!M17="","",ORCAMENTOS!M17) | L9: =IF(ORCAMENTOS!R17="","",ORCAMENTOS!R17) -> CHAPA DE ACO GALVANIZADO
A10: =IF(ORCAMENTOS!A18="","",ORCAMENTOS!A18) -> 45663 | B10: =IF(ORCAMENTOS!B18="","",ORCAMENTOS!B18) -> 8 | C10: =IF(ORCAMENTOS!C18="","",ORCAMENTOS!C18) | D10: =IF(ORCAMENTOS!D18="","",ORCAMENTOS!D18) -> GRUPO R1 | E10: =IF(ORCAMENTOS!E18="","",ORCAMENTOS!E18) -> - | F10: =IF(ORCAMENTOS!G18="","",ORCAMENTOS!G18) -> Gabriel | G10: =IF(ORCAMENTOS!H18="","",ORCAMENTOS!H18) -> Janaina | H10: =IF(ORCAMENTOS!I18="","",ORCAMENTOS!I18) -> 3232.69 | I10: =IF(ORCAMENTOS!J18="","",ORCAMENTOS!J18) | J10: =IF(ORCAMENTOS!L18="","",ORCAMENTOS!L18) -> CANCELADO | K10: =IF(ORCAMENTOS!M18="","",ORCAMENTOS!M18) -> Negociando | L10: =IF(ORCAMENTOS!R18="","",ORCAMENTOS!R18) -> -
A11: =IF(ORCAMENTOS!A19="","",ORCAMENTOS!A19) -> 45663 | B11: =IF(ORCAMENTOS!B19="","",ORCAMENTOS!B19) -> 9 | C11: =IF(ORCAMENTOS!C19="","",ORCAMENTOS!C19) | D11: =IF(ORCAMENTOS!D19="","",ORCAMENTOS!D19) -> AWA AR CONDICIONADO | E11: =IF(ORCAMENTOS!E19="","",ORCAMENTOS!E19) -> ATACADAO - LAURO DE FREITAS CAJI - BA | F11: =IF(ORCAMENTOS!G19="","",ORCAMENTOS!G19) -> Guilherme | G11: =IF(ORCAMENTOS!H19="","",ORCAMENTOS!H19) -> Maria Julia | H11: =IF(ORCAMENTOS!I19="","",ORCAMENTOS!I19) -> 175342.6 | I11: =IF(ORCAMENTOS!J19="","",ORCAMENTOS!J19) | J11: =IF(ORCAMENTOS!L19="","",ORCAMENTOS!L19) -> CANCELADO | K11: =IF(ORCAMENTOS!M19="","",ORCAMENTOS!M19) | L11: =IF(ORCAMENTOS!R19="","",ORCAMENTOS!R19) -> N/E
A12: =IF(ORCAMENTOS!A20="","",ORCAMENTOS!A20) -> 45663 | B12: =IF(ORCAMENTOS!B20="","",ORCAMENTOS!B20) -> 10 | C12: =IF(ORCAMENTOS!C20="","",ORCAMENTOS!C20) | D12: =IF(ORCAMENTOS!D20="","",ORCAMENTOS!D20) -> CONSTARCO | E12: =IF(ORCAMENTOS!E20="","",ORCAMENTOS!E20) -> - | F12: =IF(ORCAMENTOS!G20="","",ORCAMENTOS!G20) -> Fernando | G12: =IF(ORCAMENTOS!H20="","",ORCAMENTOS!H20) -> Fabricio | H12: =IF(ORCAMENTOS!I20="","",ORCAMENTOS!I20) -> 297411.92 | I12: =IF(ORCAMENTOS!J20="","",ORCAMENTOS!J20) | J12: =IF(ORCAMENTOS!L20="","",ORCAMENTOS!L20) -> CANCELADO | K12: =IF(ORCAMENTOS!M20="","",ORCAMENTOS!M20) -> PERDERAM A OBRA | L12: =IF(ORCAMENTOS!R20="","",ORCAMENTOS!R20) -> -
A13: =IF(ORCAMENTOS!A21="","",ORCAMENTOS!A21) -> 45663 | B13: =IF(ORCAMENTOS!B21="","",ORCAMENTOS!B21) -> 11 | C13: =IF(ORCAMENTOS!C21="","",ORCAMENTOS!C21) | D13: =IF(ORCAMENTOS!D21="","",ORCAMENTOS!D21) -> INOVECTOR | E13: =IF(ORCAMENTOS!E21="","",ORCAMENTOS!E21) -> ANALIA FRANCO - REQ 2.03 | F13: =IF(ORCAMENTOS!G21="","",ORCAMENTOS!G21) -> Fernando | G13: =IF(ORCAMENTOS!H21="","",ORCAMENTOS!H21) -> Eliete | H13: =IF(ORCAMENTOS!I21="","",ORCAMENTOS!I21) -> 9352.59 | I13: =IF(ORCAMENTOS!J21="","",ORCAMENTOS!J21) | J13: =IF(ORCAMENTOS!L21="","",ORCAMENTOS!L21) -> FECHADO | K13: =IF(ORCAMENTOS!M21="","",ORCAMENTOS!M21) | L13: =IF(ORCAMENTOS!R21="","",ORCAMENTOS!R21) -> -
A14: =IF(ORCAMENTOS!A22="","",ORCAMENTOS!A22) -> 45663 | B14: =IF(ORCAMENTOS!B22="","",ORCAMENTOS!B22) -> 12 | C14: =IF(ORCAMENTOS!C22="","",ORCAMENTOS!C22) | D14: =IF(ORCAMENTOS!D22="","",ORCAMENTOS!D22) -> INOVECTOR | E14: =IF(ORCAMENTOS!E22="","",ORCAMENTOS!E22) -> HOSP.OSASCO - REQ 2.04 | F14: =IF(ORCAMENTOS!G22="","",ORCAMENTOS!G22) -> Fernando | G14: =IF(ORCAMENTOS!H22="","",ORCAMENTOS!H22) -> Cristina | H14: =IF(ORCAMENTOS!I22="","",ORCAMENTOS!I22) -> 169.83 | I14: =IF(ORCAMENTOS!J22="","",ORCAMENTOS!J22) | J14: =IF(ORCAMENTOS!L22="","",ORCAMENTOS!L22) -> CANCELADO | K14: =IF(ORCAMENTOS!M22="","",ORCAMENTOS!M22) | L14: =IF(ORCAMENTOS!R22="","",ORCAMENTOS!R22) -> -
... A3186: =IF(ORCAMENTOS!A3194="","",ORCAMENTOS!A3194) | B3186: =IF(ORCAMENTOS!B3194="","",ORCAMENTOS!B3194) | C3186: =IF(ORCAMENTOS!C3194="","",ORCAMENTOS!C3194) | D3186: =IF(ORCAMENTOS!D3194="","",ORCAMENTOS!D3194) | E3186: =IF(ORCAMENTOS!E3194="","",ORCAMENTOS!E3194) | F3186: =IF(ORCAMENTOS!G3194="","",ORCAMENTOS!G3194) | G3186: =IF(ORCAMENTOS!H3194="","",ORCAMENTOS!H3194) | H3186: =IF(ORCAMENTOS!I3194="","",ORCAMENTOS!I3194) | I3186: =IF(ORCAMENTOS!J3194="","",ORCAMENTOS!J3194) | J3186: =IF(ORCAMENTOS!L3194="","",ORCAMENTOS!L3194) | K3186: =IF(ORCAMENTOS!M3194="","",ORCAMENTOS!M3194) | L3186: =IF(ORCAMENTOS!R3194="","",ORCAMENTOS!R3194)
D3188: =SUBTOTAL(9,H3:H3186) -> 171059.67 | L3188: =IF(ORCAMENTOS!R704="","",ORCAMENTOS!R704) -> -
L3189: =IF(ORCAMENTOS!R705="","",ORCAMENTOS!R705) -> -
L3190: =IF(ORCAMENTOS!R706="","",ORCAMENTOS!R706) -> -
